<?xml version="1.0" encoding="utf-8"?>
<!-- This URDF was automatically created by SolidWorks to URDF Exporter! Originally created by Stephen Brawner (brawner@gmail.com) 
     Commit Version: 1.6.0-4-g7f85cfe  Build Version: 1.6.7995.38578
     For more information, please see http://wiki.ros.org/sw_urdf_exporter -->
<robot
  name="urdf2">
  <link
    name="base_link">
    <inertial>
      <origin
        xyz="0.044092 -0.0071279 0.046916"
        rpy="0 0 0" />
      <mass
        value="7.2364" />
      <inertia
        ixx="0.023421"
        ixy="-0.00022862"
        ixz="0.00044997"
        iyy="0.051438"
        iyz="-6.949E-07"
        izz="0.067441" />
    </inertial>
    <visual>
      <origin
        xyz="0 0 0"
        rpy="0 0 0" />
      <geometry>
        <mesh
          filename="package://urdf2/meshes/base_link.STL" />
      </geometry>
      <material
        name="">
        <color
          rgba="0.75294 0.75294 0.75294 1" />
      </material>
    </visual>
    <collision>
      <origin
        xyz="0 0 0"
        rpy="0 0 0" />
      <geometry>
        <mesh
          filename="package://urdf2/meshes/base_link.STL" />
      </geometry>
    </collision>
  </link>
  <link
    name="Lidar_link">
    <inertial>
      <origin
        xyz="0.014838 0.00044768 -0.021154"
        rpy="0 0 0" />
      <mass
        value="0.031241" />
      <inertia
        ixx="8.8803E-06"
        ixy="-1.7766E-07"
        ixz="1.1303E-07"
        iyy="1.4491E-05"
        iyz="3.4608E-08"
        izz="2.2529E-05" />
    </inertial>
    <visual>
      <origin
        xyz="0 0 0"
        rpy="0 0 0" />
      <geometry>
        <mesh
          filename="package://urdf2/meshes/Lidar_link.STL" />
      </geometry>
      <material
        name="">
        <color
          rgba="0.79216 0.81961 0.93333 1" />
      </material>
    </visual>
    <collision>
      <origin
        xyz="0 0 0"
        rpy="0 0 0" />
      <geometry>
        <mesh
          filename="package://urdf2/meshes/Lidar_link.STL" />
      </geometry>
    </collision>
  </link>
  <joint
    name="Lidar_joint"
    type="fixed">
    <origin
      xyz="0.15573 0.0011914 0.1461"
      rpy="0 0 0" />
    <parent
      link="base_link" />
    <child
      link="Lidar_link" />
    <axis
      xyz="0 0 0" />
  </joint>
  <link
    name="Imu_link">
    <inertial>
      <origin
        xyz="-0.00012898 -0.0001915 -0.0038407"
        rpy="0 0 0" />
      <mass
        value="0.0009999" />
      <inertia
        ixx="2.5045E-08"
        ixy="1.0397E-10"
        ixz="-2.6856E-14"
        iyy="1.2451E-08"
        iyz="-1.1857E-14"
        izz="3.0638E-08" />
    </inertial>
    <visual>
      <origin
        xyz="0 0 0"
        rpy="0 0 0" />
      <geometry>
        <mesh
          filename="package://urdf2/meshes/Imu_link.STL" />
      </geometry>
      <material
        name="">
        <color
          rgba="0.79216 0.81961 0.93333 1" />
      </material>
    </visual>
    <collision>
      <origin
        xyz="0 0 0"
        rpy="0 0 0" />
      <geometry>
        <mesh
          filename="package://urdf2/meshes/Imu_link.STL" />
      </geometry>
    </collision>
  </link>
  <joint
    name="Imu_joint"
    type="fixed">
    <origin
      xyz="0.12649 -0.10046 0.03302"
      rpy="0 0 0" />
    <parent
      link="base_link" />
    <child
      link="Imu_link" />
    <axis
      xyz="0 0 0" />
  </joint>
  <link
    name="Right_wheel_link">
    <inertial>
      <origin
        xyz="0.00024359 -0.0295 8.0116E-11"
        rpy="0 0 0" />
      <mass
        value="0.98171" />
      <inertia
        ixx="0.001653"
        ixy="-1.0121E-05"
        ixz="1.9499E-09"
        iyy="0.0028786"
        iyz="1.7266E-11"
        izz="0.0016529" />
    </inertial>
    <visual>
      <origin
        xyz="0 0 0"
        rpy="0 0 0" />
      <geometry>
        <mesh
          filename="package://urdf2/meshes/Right_wheel_link.STL" />
      </geometry>
      <material
        name="">
        <color
          rgba="0.2 0.2 0.2 1" />
      </material>
    </visual>
    <collision>
      <origin
        xyz="0 0 0"
        rpy="0 0 0" />
      <geometry>
        <mesh
          filename="package://urdf2/meshes/Right_wheel_link.STL" />
      </geometry>
    </collision>
  </link>
  <joint
    name="right_wheel"
    type="continuous">
    <origin
      xyz="0.0016366 -0.17496 0.015"
      rpy="0 0 0" />
    <parent
      link="base_link" />
    <child
      link="Right_wheel_link" />
    <axis
      xyz="-0.0082569 0.99997 0" />
  </joint>
  <link
    name="Left_wheel_link">
    <inertial>
      <origin
        xyz="-0.00024359 0.0295 8.0116E-11"
        rpy="0 0 0" />
      <mass
        value="0.98171" />
      <inertia
        ixx="0.001653"
        ixy="-1.0121E-05"
        ixz="-2.0029E-09"
        iyy="0.0028786"
        iyz="-1.7704E-11"
        izz="0.0016529" />
    </inertial>
    <visual>
      <origin
        xyz="0 0 0"
        rpy="0 0 0" />
      <geometry>
        <mesh
          filename="package://urdf2/meshes/Left_wheel_link.STL" />
      </geometry>
      <material
        name="">
        <color
          rgba="0.2 0.2 0.2 1" />
      </material>
    </visual>
    <collision>
      <origin
        xyz="0 0 0"
        rpy="0 0 0" />
      <geometry>
        <mesh
          filename="package://urdf2/meshes/Left_wheel_link.STL" />
      </geometry>
    </collision>
  </link>
  <joint
    name="left_wheel"
    type="continuous">
    <origin
      xyz="-0.0012534 0.17503 0.015"
      rpy="0 0 0" />
    <parent
      link="base_link" />
    <child
      link="Left_wheel_link" />
    <axis
      xyz="0.0082569 -0.99997 0" />
  </joint>
</robot>
